<mujoco model="unnamed">
  <compiler angle="radian"/>

  <asset>
    <mesh name="base_link" file="../meshes/base_link.stl"/>
    <mesh name="gripper_moving_1" file="../meshes/gripper_moving_1.stl"/>
    <mesh name="gripper_static_1" file="../meshes/gripper_static_1.stl"/>
    <mesh name="link1_1" file="../meshes/link1_1.stl"/>
    <mesh name="link2_1" file="../meshes/link2_1.stl"/>
    <mesh name="link3_1" file="../meshes/link3_1.stl"/>
    <mesh name="link4_1" file="../meshes/link4_1.stl"/>
  </asset>

  <default>
    <default class="low_cost_robot">
      <general biastype="affine"/>
      <!-- NOTE: the joint pos are defined in world frame, so they're built by summing over urdf relative joint positioning -->
      <!-- NOTE: values other than axis and pos here have not been properly identified -->
      <joint axis="0 1 0"/>
      <default class="joint1">
        <!-- <joint axis="0 0 1" range="-3.14158 3.14158" damping="0.1"/> -->
        <position ctrlrange="-3.14158 3.14158" kp="1000" dampratio="1"/>
      </default>
      <default class="joint2">
        <!-- <joint axis="0 0 1" range="-3.14158 3.14158" damping="0.1"/> -->
        <position ctrlrange="-3.14158 3.14158" kp="1000" dampratio="1"/>
      </default>
      <default class="joint3">
        <!-- <joint axis="0 0 1" range="-3.14158 3.14158" damping="0.1"/> -->
        <position ctrlrange="-3.14158 3.14158" kp="1000" dampratio="1"/>
      </default>
      <default class="joint4">
        <!-- <joint axis="0 0 1" range="-3.14158 3.14158" damping="0.1"/> -->
        <position ctrlrange="-3.14158 3.14158" kp="1000" dampratio="1"/>
      </default>
      <default class="joint5">
        <!-- <joint axis="0 0 1" range="-3.14158 3.14158" damping="0.1"/> -->
        <position ctrlrange="-3.14158 3.14158" kp="1000" dampratio="1"/>
      </default>
      <default class="joint6">
        <!-- <joint axis="0 0 1" range="-3.14158 3.14158" damping="0.1"/> -->
        <position ctrlrange="0.032 2.45" kp="1000" dampratio="1"/>
      </default>
    </default>
  </default>

  <worldbody>
    <geom name="base_link_collision" type="mesh" mesh="base_link" rgba="0.7 0.7 0.7 1"/>
    <body name="link1_1_link" pos="0 0 39.95">
      <inertial pos="1.75295 -11.1599 11.4137" quat="0.454483 0.479346 -0.578478 0.478577" mass="0.000001" diaginertia="0.30699 0.282424 0.179345"/>
      <joint name="joint1" pos="0 0 0" axis="0 0 1" range="-3.14 3.14"/>
      <geom name="link1_1_collision" pos="0 0 -39.95" quat="1 0 0 0" type="mesh" mesh="link1_1" rgba="0.7 0.7 0.7 1"/>
      <body name="link2_1_link" pos="0 0 16.35">
        <inertial pos="0.15745 -1.21712 71.6057" quat="0.666267 -0.0339819 0.0538212 0.742992" mass="0.000001" diaginertia="2.15196 2.11655 0.208454"/>
        <joint name="joint2" pos="0 0 0" axis="1 0 0" range="-3.14 3.14"/>
        <geom name="link2_1_collision" pos="0.20001 0 -56.3" quat="1 0 0 0" type="mesh" mesh="link2_1" rgba="0.7 0.7 0.7 1"/>
        <body name="link3_1_link" pos="0 14.7203 108.252">
          <inertial pos="0.12239 50.7709 2.94563" quat="0.505066 0.495637 -0.507447 0.49168" mass="0.000001" diaginertia="1.37019 1.32214 0.116534"/>
          <joint name="joint3" pos="0 0 0" axis="1 0 0" range="-3.14 3.14"/>
          <geom name="link3_1_collision" pos="0 -14.7203 -164.552" quat="1 0 0 0" type="mesh" mesh="link3_1" rgba="0.7 0.7 0.7 1"/>
          <body name="link4_1_link" pos="0 90.5377 2.842">
            <inertial pos="-4.56404 0.0086 -26.5781" quat="0.698383 0.11456 0.122012 0.695881" mass="0.000001" diaginertia="0.289697 0.199614 0.14223"/>
            <joint name="joint4" pos="0 0 0" axis="1 0 0" range="-3.14 3.14"/>
            <geom name="link4_1_collision" pos="0 -105.258 -167.394" quat="1 0 0 0" type="mesh" mesh="link4_1" rgba="0.7 0.7 0.7 1"/>
            <body name="gripper_static_link" pos="1.52832 0.007 -45">
              <inertial pos="5.44087 0.11501 -19.0509" quat="0.694136 -0.208599 -0.203687 0.658159" mass="0.000001" diaginertia="0.377576 0.337748 0.139385"/>
              <joint name="joint5" pos="0 0 0" axis="0 0 1" range="-3.14 3.14"/>
              <geom name="gripper_static_1_collision" pos="-1.52832 -105.265 -122.394" quat="1 0 0 0" type="mesh" mesh="gripper_static_1" rgba="0.7 0.7 0.7 1"/>
              <body name="gripper_moving_link" pos="-7.4 -0.249 -13.15">
                <inertial pos="1.09487 0.31001 -25.1094" quat="0.999337 0.0142204 -0.0334836 0.00132207" mass="0.000001" diaginertia="0.373047 0.29003 0.116983"/>
                <joint name="joint6" pos="0 0 0" axis="0 1 0" range="-3.14 3.14"/>
                <geom name="gripper_moving_1_collision" pos="5.87168 -105.016 -109.244" type="mesh" mesh="gripper_moving_1" rgba="0.7 0.7 0.7 1"/>
              </body>
            </body>
          </body>
        </body>
      </body>
    </body>
  </worldbody>

  <actuator>
    <position class="joint1" name="joint1" joint="joint1"/>
    <position class="joint2" name="joint2" joint="joint2"/>
    <position class="joint3" name="joint3" joint="joint3"/>
    <position class="joint4" name="joint4" joint="joint4"/>
    <position class="joint5" name="joint5" joint="joint5"/>
    <position class="joint6" name="joint6" joint="joint6"/>
  </actuator>

</mujoco>
